Traceback (most recent call last):
  File "/Users/nanaboateng/opt/anaconda3/envs/solving_pde_mooc/lib/python3.10/site-packages/jupyter_cache/executors/utils.py", line 51, in single_nb_execution
    executenb(
  File "/Users/nanaboateng/opt/anaconda3/envs/solving_pde_mooc/lib/python3.10/site-packages/nbclient/client.py", line 1204, in execute
    return NotebookClient(nb=nb, resources=resources, km=km, **kwargs).execute()
  File "/Users/nanaboateng/opt/anaconda3/envs/solving_pde_mooc/lib/python3.10/site-packages/nbclient/util.py", line 84, in wrapped
    return just_run(coro(*args, **kwargs))
  File "/Users/nanaboateng/opt/anaconda3/envs/solving_pde_mooc/lib/python3.10/site-packages/nbclient/util.py", line 62, in just_run
    return loop.run_until_complete(coro)
  File "/Users/nanaboateng/opt/anaconda3/envs/solving_pde_mooc/lib/python3.10/asyncio/base_events.py", line 646, in run_until_complete
    return future.result()
  File "/Users/nanaboateng/opt/anaconda3/envs/solving_pde_mooc/lib/python3.10/site-packages/nbclient/client.py", line 663, in async_execute
    await self.async_execute_cell(
  File "/Users/nanaboateng/opt/anaconda3/envs/solving_pde_mooc/lib/python3.10/site-packages/nbclient/client.py", line 965, in async_execute_cell
    await self._check_raise_for_error(cell, cell_index, exec_reply)
  File "/Users/nanaboateng/opt/anaconda3/envs/solving_pde_mooc/lib/python3.10/site-packages/nbclient/client.py", line 862, in _check_raise_for_error
    raise CellExecutionError.from_cell_and_msg(cell, exec_reply_content)
nbclient.exceptions.CellExecutionError: An error occurred while executing the following cell:
------------------
print_name_and_data('Luke')
------------------

[0;31m---------------------------------------------------------------------------[0m
[0;31mTypeError[0m                                 Traceback (most recent call last)
Input [0;32mIn [13][0m, in [0;36m<cell line: 1>[0;34m()[0m
[0;32m----> 1[0m [43mprint_name_and_data[49m[43m([49m[38;5;124;43m'[39;49m[38;5;124;43mLuke[39;49m[38;5;124;43m'[39;49m[43m)[49m

[0;31mTypeError[0m: print_name_and_data() missing 3 required positional arguments: 'age', 'height', and 'weight'
TypeError: print_name_and_data() missing 3 required positional arguments: 'age', 'height', and 'weight'

